<mujoco model="arm3d">
    <compiler inertiafromgeom="true" angle="radian" coordinate="local" />
    <option timestep="0.01" gravity="0 0 -2.81" iterations="20" integrator="Euler" />
    
    <default>
        <joint armature='0.04' damping="1" limited="true"/>
        <geom friction=".8 .1 .1" density="300" margin="0.002" condim="1" contype="1" conaffinity="1"/>
    </default>
    
    <worldbody>
        <light diffuse=".5 .5 .5" pos="0 0 3" dir="0 0 -1"/>
        <geom type="plane" pos="0 0.5 -0.15" size="2 2 0.1" contype="1" conaffinity="1"/>

        <body name="palm" pos="0 -1 0">
            <geom type="capsule" fromto="0 0 -0.1 0 0 0.1" size="0.12"/>
            <body name="proximal_1" pos="0 0 -0.075" >
                <!--<joint name="proximal_j_1" type="hinge" pos="0 0 0" axis="0 0 1" range="-2.5236 2.3963" damping="5.0" />-->
                <geom type="capsule"  fromto="0 0 0 0.4 0 0" size="0.06" contype="1" conaffinity="1"/>
                <body name="distal_1" pos="0.4 0 0">
                    <joint name="distal_j_1" type="hinge" pos="0 0 0" axis="0 0 1" range="-2.3213 2.3" damping="1.0"/>
                    <geom type="capsule"  fromto="0 0 0 0 0 0.4" size="0.06" contype="1" conaffinity="1"/>
                    <body name="distal_2" pos="0 0 0.4" axisangle="0 0 1 -1.57">
                        <joint name="distal_j_2" type="hinge" pos="0 0 0" axis="0 1 0" range="-0.785 0" damping="1.0"/>
                        <geom type="capsule" fromto="0 0 0 0.3 0 0.3" size="0.06" contype="1" conaffinity="1"/>
                        <body name="distal_4" pos="0.3 0 0.3">
                            <!--<site name="tip arml" pos="0.1 -0.2 0" size="0.01" />
                            <site name="tip armr" pos="0.1 0.2 0" size="0.01" />-->
                            <!--<joint name="distal_j_3" type="hinge" pos="0 0 0" axis="0 1 0" range="-0.785 0" damping="0.5"/>-->

                            <geom type="capsule" fromto="0 -0.1 0 0 0.1 0" size="0.04" contype="1" conaffinity="1" />
                            <body name="holder" pos="0.1 0 0">
                                <geom type="box" pos="0 0 0.01" size="0.1 0.1 0.01" contype="1" conaffinity="0"/>
                                <geom type="box" pos="0.0 0.1 0.05" size="0.1 0.01 0.075" contype="1" conaffinity="0"/>
                                <geom type="box" pos="0.0 -0.1 0.05" size="0.1 0.01 0.075" contype="1" conaffinity="0"/>
                                <geom type="box" pos="0.1 0 0.05" size="0.01 0.1 0.075" contype="1" conaffinity="0"/>
                            </body>

                            <!--<geom type="capsule" fromto="0 -0.2 0 0 0.2 0" size="0.04" contype="1" conaffinity="1" />
                            <geom type="capsule" fromto="0 -0.2 0 0.2 -0.2 0" size="0.04" contype="1" conaffinity="1" />
                            <geom type="capsule" fromto="0 0.2 0 0.2 0.2 0" size="0.04" contype="1" conaffinity="1" />-->
                        </body>
                    </body>
                </body>
            </body>
        </body>

        <body name="goal" pos="0 0 -0.145">
            <geom rgba="1. 0. 0. 1" type="cylinder" size="0.17 0.005 0.2" density='0.00001' contype="0" conaffinity="0"/>
            <joint name="goal_slidey" type="slide" pos="0 0 0" axis="0 1 0" range="-10.3213 10.3" damping="0.5"/>
            <joint name="goal_slidex" type="slide" pos="0 0 0" axis="1 0 0" range="-10.3213 10.3" damping="0.5"/> 
        </body>
        
        <body name="ball" pos="0.40 -1.4 0.8">
            <geom rgba="1. 1. 1. 1" type="sphere" size="0.05 0.05 0.1" density='0.00001' contype="1" conaffinity="1"/>
            <joint name="ball_free" type="free" armature='0' damping="0" limited="false"/>
        </body>

    </worldbody>

    <actuator>
        <!--<motor joint="proximal_j_1" ctrlrange="-3 3" ctrllimited="true"/>-->
        <motor joint="distal_j_1" ctrlrange="-3 3" ctrllimited="true"/>
        <motor joint="distal_j_2" ctrlrange="-5 5" ctrllimited="true"/>
        <!--<motor joint="distal_j_3" ctrlrange="-10 10" ctrllimited="true"/>-->
    </actuator>
</mujoco>
